<?xml version="1.0" ?>
<!-- =================================================================================== -->
<!-- |    This document was autogenerated by xacro from robotis_op2.urdf.xacro         | -->
<!-- |    EDITING THIS FILE BY HAND IS NOT RECOMMENDED                                 | -->
<!-- =================================================================================== -->
<robot name="robotis_op2">
  <!-- <xacro:property name="pi" value="3.141592654" /> -->
  <!-- head links -->
  <!-- left arm links -->
  <!-- right arm links -->
  <!-- left leg links -->
  <!-- right leg links -->
  <!-- <xacro:property name="pi" value="3.141592654" /> -->
  <!-- <xacro:property name="pi" value="3.141592654" /> -->
  <!-- <xacro:property name="pi" value="3.141592654" /> -->
  <gazebo>
    <plugin filename="libgazebo_ros_control.so" name="gazebo_ros_control">
      <robotNamespace>/robotis_op2</robotNamespace>
      <robotSimType>gazebo_ros_control/DefaultRobotHWSim</robotSimType>
    </plugin>
  </gazebo>
  <gazebo>
    <plugin filename="libgazebo_ros_p3d.so" name="ground_truth">
      <frameName>map</frameName>
      <bodyName>base_link</bodyName>
      <topicName>odom</topicName>
      <updateRate>100.0</updateRate>
    </plugin>
  </gazebo>
  <gazebo reference="base_link">
    <selfCollide>false</selfCollide>
  </gazebo>
  <!-- body link -->
  <gazebo reference="body_link">
    <mu1>0.5</mu1>
    <mu2>0.5</mu2>
    <selfCollide>false</selfCollide>
  </gazebo>
  <!-- head links -->
  <gazebo reference="head_pan_link">
    <mu1>0.5</mu1>
    <mu2>0.5</mu2>
    <selfCollide>false</selfCollide>
  </gazebo>
  <gazebo reference="head_tilt_link">
    <mu1>0.5</mu1>
    <mu2>0.5</mu2>
    <selfCollide>false</selfCollide>
  </gazebo>
  <gazebo reference="head_cam_link">
    <selfCollide>false</selfCollide>
  </gazebo>
  <!-- left arm links -->
  <gazebo reference="l_back_link">
    <selfCollide>false</selfCollide>
  </gazebo>
  <gazebo reference="l_sho_pitch_link">
    <mu1>0.5</mu1>
    <mu2>0.5</mu2>
    <selfCollide>false</selfCollide>
  </gazebo>
  <gazebo reference="l_sho_roll_link">
    <mu1>0.5</mu1>
    <mu2>0.5</mu2>
    <selfCollide>false</selfCollide>
  </gazebo>
  <gazebo reference="l_el_link">
    <mu1>0.5</mu1>
    <mu2>0.5</mu2>
    <selfCollide>false</selfCollide>
  </gazebo>
  <!-- right arm links -->
  <gazebo reference="r_back_link">
    <selfCollide>false</selfCollide>
  </gazebo>
  <gazebo reference="r_sho_pitch_link">
    <mu1>0.5</mu1>
    <mu2>0.5</mu2>
    <selfCollide>false</selfCollide>
  </gazebo>
  <gazebo reference="r_sho_roll_link">
    <mu1>0.5</mu1>
    <mu2>0.5</mu2>
    <selfCollide>false</selfCollide>
  </gazebo>
  <gazebo reference="r_sho_el_link">
    <mu1>0.5</mu1>
    <mu2>0.5</mu2>
    <selfCollide>false</selfCollide>
  </gazebo>
  <!-- left leg links -->
  <gazebo reference="l_hip_yaw_link">
    <mu1>0.5</mu1>
    <mu2>0.5</mu2>
    <selfCollide>false</selfCollide>
  </gazebo>
  <gazebo reference="l_hip_roll_link">
    <mu1>0.5</mu1>
    <mu2>0.5</mu2>
    <selfCollide>false</selfCollide>
  </gazebo>
  <gazebo reference="l_hip_pitch_link">
    <mu1>0.5</mu1>
    <mu2>0.5</mu2>
    <selfCollide>false</selfCollide>
  </gazebo>
  <gazebo reference="l_knee_link">
    <mu1>0.5</mu1>
    <mu2>0.5</mu2>
    <selfCollide>false</selfCollide>
  </gazebo>
  <gazebo reference="l_ank_pitch_link">
    <mu1>0.5</mu1>
    <mu2>0.5</mu2>
    <selfCollide>false</selfCollide>
  </gazebo>
  <gazebo reference="l_ank_roll_link">
    <mu1>9000</mu1>
    <mu2>9000</mu2>
    <kp>1000000.0</kp>
    <kd>10.0</kd>
    <minDepth>0.001</minDepth>
    <maxContacts>1</maxContacts>
    <selfCollide>false</selfCollide>
  </gazebo>
  <!-- right leg links -->
  <gazebo reference="r_hip_yaw_link">
    <mu1>0.5</mu1>
    <mu2>0.5</mu2>
    <selfCollide>false</selfCollide>
  </gazebo>
  <gazebo reference="r_hip_roll_link">
    <mu1>0.5</mu1>
    <mu2>0.5</mu2>
    <selfCollide>false</selfCollide>
  </gazebo>
  <gazebo reference="r_hip_pitch_link">
    <mu1>0.5</mu1>
    <mu2>0.5</mu2>
    <selfCollide>false</selfCollide>
  </gazebo>
  <gazebo reference="r_knee_link">
    <mu1>0.5</mu1>
    <mu2>0.5</mu2>
    <selfCollide>false</selfCollide>
  </gazebo>
  <gazebo reference="r_ank_pitch_link">
    <mu1>0.5</mu1>
    <mu2>0.5</mu2>
    <selfCollide>false</selfCollide>
  </gazebo>
  <gazebo reference="r_ank_roll_link">
    <mu1>9000</mu1>
    <mu2>9000</mu2>
    <kp>1000000.0</kp>
    <kd>10.0</kd>
    <minDepth>0.001</minDepth>
    <maxContacts>1</maxContacts>
    <selfCollide>false</selfCollide>
  </gazebo>
  <!-- head camera -->
  <gazebo reference="head_cam_link">
    <sensor name="camera" type="camera">
      <pose>-0.050000 -0.010000 0.000000 -1.5708 0.000000 -3.141592</pose>
      <camera name="__default__">
        <horizontal_fov>1.012300</horizontal_fov>
        <image>
          <width>320</width>
          <height>200</height>
        </image>
        <clip>
          <near>0.001000</near>
          <far>100.000000</far>
        </clip>
      </camera>
      <always_on>1</always_on>
      <update_rate>30.000000</update_rate>
      <visualize>1</visualize>
      <plugin filename="libgazebo_ros_camera.so" name="camera_controller">
        <alwaysOn>true</alwaysOn>
        <updateRate>30</updateRate>
        <cameraName>robotis_op2/camera</cameraName>
        <imageTopicName>image_raw</imageTopicName>
        <cameraInfoTopicName>camera_info</cameraInfoTopicName>
        <frameName>camera_link</frameName>
        <hackBaseline>0.07</hackBaseline>
        <distortionK1>0.0</distortionK1>
        <distortionK2>0.0</distortionK2>
        <distortionK3>0.0</distortionK3>
        <distortionT1>0.0</distortionT1>
        <distortionT2>0.0</distortionT2>
      </plugin>
    </sensor>
  </gazebo>
  <!-- imu sensor -->
  <gazebo>
    <plugin filename="libhector_gazebo_ros_imu.so" name="gazebo_ros_imu">
      <bodyName>body_link</bodyName>
      <updateRate>50</updateRate>
      <serviceName>/robotis_op2/imu_service</serviceName>
      <topicName>/robotis_op2/imu</topicName>
      <gaussianNoise>0</gaussianNoise>
      <xyzOffset>0 0 0</xyzOffset>
      <rpyOffset>0 0 -0.703220730592</rpyOffset>
    </plugin>
  </gazebo>
  <!-- base link -->
  <link name="base_link"/>
  <joint name="base_joint" type="fixed">
    <parent link="base_link"/>
    <child link="body_link"/>
  </joint>
  <!-- body link -->
  <link name="body_link">
    <visual>
      <origin rpy="0 0 -1.5707963267948966" xyz="0 0 0"/>
      <geometry>
        <mesh filename="package://robot_description/models/robotis_op2/meshes/geo_op_body.stl" scale="0.001 0.001 0.001"/>
      </geometry>
      <material name="Grey">
        <color rgba="0.60 0.60 0.60 1.0"/>
      </material>
    </visual>
    <collision>
      <origin rpy="0 0 -1.5707963267948966" xyz="0 0 0"/>
      <geometry>
        <mesh filename="package://robot_description/models/robotis_op2/meshes/geo_op_body.stl" scale="0.001 0.001 0.001"/>
      </geometry>
      <material name="Grey">
        <color rgba="0.60 0.60 0.60 1.0"/>
      </material>
    </collision>
    <inertial>
      <origin xyz="0 0 0"/>
      <mass value="0.975"/>
      <inertia ixx="1.0" ixy="0.0" ixz="0.0" iyy="1.0" iyz="0.0" izz="0.0"/>
    </inertial>
  </link>
  <joint name="head_pan" type="revolute">
    <parent link="body_link"/>
    <child link="head_pan_link"/>
    <origin rpy="0 0 0" xyz="0 0 0.0205"/>
    <axis xyz="0 0 1"/>
    <limit effort="2.8" lower="-2.6179939" upper="2.6179939" velocity="5.6548668"/>
  </joint>
  <transmission name="head_pan_tran">
    <type>transmission_interface/SimpleTransmission</type>
    <joint name="head_pan">
      <hardwareInterface>hardware_interface/EffortJointInterface</hardwareInterface>
    </joint>
    <actuator name="head_pan_motor">
      <hardwareInterface>hardware_interface/EffortJointInterface</hardwareInterface>
      <mechanicalReduction>1</mechanicalReduction>
    </actuator>
  </transmission>
  <!-- head pan link -->
  <link name="head_pan_link">
    <visual>
      <origin rpy="0 0 -1.5707963267948966" xyz="0 0 0.03"/>
      <geometry>
        <mesh filename="package://robot_description/models/robotis_op2/meshes/geo_op_neck.stl" scale="0.001 0.001 0.001"/>
      </geometry>
      <material name="Grey">
        <color rgba="0.60 0.60 0.60 1.0"/>
      </material>
    </visual>
    <collision>
      <origin rpy="0 0 -1.5707963267948966" xyz="0 0 0.03"/>
      <geometry>
        <mesh filename="package://robot_description/models/robotis_op2/meshes/geo_op_neck.stl" scale="0.001 0.001 0.001"/>
      </geometry>
      <material name="Grey">
        <color rgba="0.60 0.60 0.60 1.0"/>
      </material>
    </collision>
    <inertial>
      <origin xyz="0 0 0"/>
      <mass value="0.0243"/>
      <inertia ixx="1.0" ixy="0.0" ixz="0.0" iyy="1.0" iyz="0.0" izz="0.0"/>
    </inertial>
  </link>
  <joint name="head_tilt" type="revolute">
    <parent link="head_pan_link"/>
    <child link="head_tilt_link"/>
    <origin rpy="0 0.5759586531581288 0" xyz="0 0 0.03"/>
    <axis xyz="0 -1 0"/>
    <limit effort="2.8" lower="-2.6179939" upper="2.6179939" velocity="5.6548668"/>
  </joint>
  <transmission name="head_tilt_tran">
    <type>transmission_interface/SimpleTransmission</type>
    <joint name="head_tilt">
      <hardwareInterface>hardware_interface/EffortJointInterface</hardwareInterface>
    </joint>
    <actuator name="head_tilt_motor">
      <hardwareInterface>hardware_interface/EffortJointInterface</hardwareInterface>
      <mechanicalReduction>1</mechanicalReduction>
    </actuator>
  </transmission>
  <!-- head tilt link -->
  <link name="head_tilt_link">
    <visual>
      <origin rpy="0 3.141592653589793 1.5707963267948966" xyz="0 0 0"/>
      <geometry>
        <mesh filename="package://robot_description/models/robotis_op2/meshes/geo_op_head.stl" scale="0.001 0.001 0.001"/>
      </geometry>
      <material name="Grey">
        <color rgba="0.60 0.60 0.60 1.0"/>
      </material>
    </visual>
    <collision>
      <origin rpy="0 3.141592653589793 1.5707963267948966" xyz="0 0 0"/>
      <geometry>
        <mesh filename="package://robot_description/models/robotis_op2/meshes/geo_op_head.stl" scale="0.001 0.001 0.001"/>
      </geometry>
      <material name="Grey">
        <color rgba="0.60 0.60 0.60 1.0"/>
      </material>
    </collision>
    <inertial>
      <origin xyz="0 0 0"/>
      <mass value="0.158"/>
      <inertia ixx="1.0" ixy="0.0" ixz="0.0" iyy="1.0" iyz="0.0" izz="0.0"/>
    </inertial>
  </link>
  <joint name="head_cam" type="fixed">
    <parent link="head_tilt_link"/>
    <child link="head_cam_link"/>
    <origin rpy="0 0 0" xyz="0.0332 0 0.0344"/>
  </joint>
  <!-- head camera link -->
  <link name="head_cam_link"/>
  <!-- left shoulder pitch link -->
  <joint name="l_sho_pitch" type="revolute">
    <parent link="body_link"/>
    <child link="l_sho_pitch_link"/>
    <origin rpy="0 0 0" xyz="0 0.0575 0"/>
    <axis xyz="0 1 0"/>
    <limit effort="2.8" lower="-2.6179939" upper="2.6179939" velocity="5.6548668"/>
  </joint>
  <transmission name="l_sho_pitch_tran">
    <type>transmission_interface/SimpleTransmission</type>
    <joint name="l_sho_pitch">
      <hardwareInterface>hardware_interface/EffortJointInterface</hardwareInterface>
    </joint>
    <actuator name="l_sho_pitch_motor">
      <hardwareInterface>hardware_interface/EffortJointInterface</hardwareInterface>
      <mechanicalReduction>1</mechanicalReduction>
    </actuator>
  </transmission>
  <link name="l_sho_pitch_link">
    <visual>
      <origin rpy="0 0 -1.5707963267948966" xyz="0 0 0"/>
      <geometry>
        <mesh filename="package://robot_description/models/robotis_op2/meshes/geo_op_left_shoulder.stl" scale="0.001 0.001 0.001"/>
      </geometry>
      <material name="Grey">
        <color rgba="0.60 0.60 0.60 1.0"/>
      </material>
    </visual>
    <collision>
      <origin rpy="0 0 -1.5707963267948966" xyz="0 0 0"/>
      <geometry>
        <mesh filename="package://robot_description/models/robotis_op2/meshes/geo_op_left_shoulder.stl" scale="0.001 0.001 0.001"/>
      </geometry>
      <material name="Grey">
        <color rgba="0.60 0.60 0.60 1.0"/>
      </material>
    </collision>
    <inertial>
      <origin xyz="0 0 0"/>
      <mass value="0.0259"/>
      <inertia ixx="1.0" ixy="0.0" ixz="0.0" iyy="1.0" iyz="0.0" izz="0.0"/>
    </inertial>
  </link>
  <joint name="l_sho_roll" type="revolute">
    <parent link="l_sho_pitch_link"/>
    <child link="l_sho_roll_link"/>
    <origin rpy="0.7853981633974483 0 0" xyz="0 0.0245 -0.016"/>
    <axis xyz="-1 0 0"/>
    <limit effort="2.8" lower="-2.6179939" upper="2.6179939" velocity="5.648668"/>
  </joint>
  <transmission name="l_sho_roll_tran">
    <type>transmission_interface/SimpleTransmission</type>
    <joint name="l_sho_roll">
      <hardwareInterface>hardware_interface/EffortJointInterface</hardwareInterface>
    </joint>
    <actuator name="l_sho_roll_motor">
      <hardwareInterface>hardware_interface/EffortJointInterface</hardwareInterface>
      <mechanicalReduction>1</mechanicalReduction>
    </actuator>
  </transmission>
  <!-- left shoulder roll link -->
  <link name="l_sho_roll_link">
    <visual>
      <origin rpy="0 0 -1.5707963267948966" xyz="0 0 0"/>
      <geometry>
        <mesh filename="package://robot_description/models/robotis_op2/meshes/geo_op_left_upper-arm.stl" scale="0.001 0.001 0.001"/>
      </geometry>
      <material name="Grey">
        <color rgba="0.60 0.60 0.60 1.0"/>
      </material>
    </visual>
    <collision>
      <origin rpy="0 0 -1.5707963267948966" xyz="0 0 0"/>
      <geometry>
        <mesh filename="package://robot_description/models/robotis_op2/meshes/geo_op_left_upper-arm.stl" scale="0.001 0.001 0.001"/>
      </geometry>
      <material name="Grey">
        <color rgba="0.60 0.60 0.60 1.0"/>
      </material>
    </collision>
    <inertial>
      <origin xyz="0 0 0"/>
      <mass value="0.168"/>
      <inertia ixx="1.0" ixy="0.0" ixz="0.0" iyy="1.0" iyz="0.0" izz="0.0"/>
    </inertial>
  </link>
  <!-- left elbow link -->
  <joint name="l_el" type="revolute">
    <parent link="l_sho_roll_link"/>
    <child link="l_el_link"/>
    <origin rpy="0 -1.5707963267948966 0" xyz="0.016 0 -0.06"/>
    <axis xyz="0 1 0"/>
    <limit effort="2.8" lower="-2.6179939" upper="2.6179939" velocity="5.6548668"/>
  </joint>
  <transmission name="l_el_tran">
    <type>transmission_interface/SimpleTransmission</type>
    <joint name="l_el">
      <hardwareInterface>hardware_interface/EffortJointInterface</hardwareInterface>
    </joint>
    <actuator name="l_el_motor">
      <hardwareInterface>hardware_interface/EffortJointInterface</hardwareInterface>
      <mechanicalReduction>1</mechanicalReduction>
    </actuator>
  </transmission>
  <link name="l_el_link">
    <visual>
      <origin rpy="0 0 -1.5707963267948966" xyz="0 0 0"/>
      <geometry>
        <mesh filename="package://robot_description/models/robotis_op2/meshes/geo_op_left_lower-arm.stl" scale="0.001 0.001 0.001"/>
      </geometry>
      <material name="Grey">
        <color rgba="0.60 0.60 0.60 1.0"/>
      </material>
    </visual>
    <collision>
      <origin rpy="0 0 -1.5707963267948966" xyz="0 0 0"/>
      <geometry>
        <mesh filename="package://robot_description/models/robotis_op2/meshes/geo_op_left_lower-arm.stl" scale="0.001 0.001 0.001"/>
      </geometry>
      <material name="Grey">
        <color rgba="0.60 0.60 0.60 1.0"/>
      </material>
    </collision>
    <inertial>
      <origin xyz="0 0 0"/>
      <mass value="0.0592"/>
      <inertia ixx="1.0" ixy="0.0" ixz="0.0" iyy="1.0" iyz="0.0" izz="0.0"/>
    </inertial>
  </link>
  <!-- right shoulder pitch link -->
  <joint name="r_sho_pitch" type="revolute">
    <parent link="body_link"/>
    <child link="r_sho_pitch_link"/>
    <origin rpy="0 0 0" xyz="0 -0.0575 0"/>
    <axis xyz="0 -1 0"/>
    <limit effort="2.8" lower="-2.6179939" upper="2.6179939" velocity="5.6548668"/>
  </joint>
  <transmission name="r_sho_pitch_tran">
    <type>transmission_interface/SimpleTransmission</type>
    <joint name="r_sho_pitch">
      <hardwareInterface>hardware_interface/EffortJointInterface</hardwareInterface>
    </joint>
    <actuator name="r_sho_pitch_motor">
      <hardwareInterface>hardware_interface/EffortJointInterface</hardwareInterface>
      <mechanicalReduction>1</mechanicalReduction>
    </actuator>
  </transmission>
  <link name="r_sho_pitch_link">
    <visual>
      <origin rpy="0 0 -1.5707963267948966" xyz="0 0 0"/>
      <geometry>
        <mesh filename="package://robot_description/models/robotis_op2/meshes/geo_op_right_shoulder.stl" scale="0.001 0.001 0.001"/>
      </geometry>
      <material name="Grey">
        <color rgba="0.60 0.60 0.60 1.0"/>
      </material>
    </visual>
    <collision>
      <origin rpy="0 0 -1.5707963267948966" xyz="0 0 0"/>
      <geometry>
        <mesh filename="package://robot_description/models/robotis_op2/meshes/geo_op_right_shoulder.stl" scale="0.001 0.001 0.001"/>
      </geometry>
      <material name="Grey">
        <color rgba="0.60 0.60 0.60 1.0"/>
      </material>
    </collision>
    <inertial>
      <origin xyz="0 0 0"/>
      <mass value="0.0259"/>
      <inertia ixx="1.0" ixy="0.0" ixz="0.0" iyy="1.0" iyz="0.0" izz="0.0"/>
    </inertial>
  </link>
  <!-- right shoulder roll link -->
  <joint name="r_sho_roll" type="revolute">
    <parent link="r_sho_pitch_link"/>
    <child link="r_sho_roll_link"/>
    <origin rpy="-0.7853981633974483 0 0" xyz="0 -0.0245 -0.016"/>
    <axis xyz="-1 0 0"/>
    <limit effort="2.8" lower="-2.6179939" upper="2.6179939" velocity="5.648668"/>
  </joint>
  <transmission name="r_sho_roll_tran">
    <type>transmission_interface/SimpleTransmission</type>
    <joint name="r_sho_roll">
      <hardwareInterface>hardware_interface/EffortJointInterface</hardwareInterface>
    </joint>
    <actuator name="r_sho_roll_motor">
      <hardwareInterface>hardware_interface/EffortJointInterface</hardwareInterface>
      <mechanicalReduction>1</mechanicalReduction>
    </actuator>
  </transmission>
  <link name="r_sho_roll_link">
    <visual>
      <origin rpy="0 0 -1.5707963267948966" xyz="0 0 0"/>
      <geometry>
        <mesh filename="package://robot_description/models/robotis_op2/meshes/geo_op_right_upper-arm.stl" scale="0.001 0.001 0.001"/>
      </geometry>
      <material name="Grey">
        <color rgba="0.60 0.60 0.60 1.0"/>
      </material>
    </visual>
    <collision>
      <origin rpy="0 0 -1.5707963267948966" xyz="0 0 0"/>
      <geometry>
        <mesh filename="package://robot_description/models/robotis_op2/meshes/geo_op_right_upper-arm.stl" scale="0.001 0.001 0.001"/>
      </geometry>
      <material name="Grey">
        <color rgba="0.60 0.60 0.60 1.0"/>
      </material>
    </collision>
    <inertial>
      <origin xyz="0 0 0"/>
      <mass value="0.168"/>
      <inertia ixx="1.0" ixy="0.0" ixz="0.0" iyy="1.0" iyz="0.0" izz="0.0"/>
    </inertial>
  </link>
  <!-- right elbow link -->
  <joint name="r_el" type="revolute">
    <parent link="r_sho_roll_link"/>
    <child link="r_el_link"/>
    <origin rpy="0 -1.5707963267948966 0" xyz="0.016 0 -0.06"/>
    <axis xyz="0 -1 0"/>
    <limit effort="2.8" lower="-2.6179939" upper="2.6179939" velocity="5.6548668"/>
  </joint>
  <transmission name="r_el_tran">
    <type>transmission_interface/SimpleTransmission</type>
    <joint name="r_el">
      <hardwareInterface>hardware_interface/EffortJointInterface</hardwareInterface>
    </joint>
    <actuator name="r_el_motor">
      <hardwareInterface>hardware_interface/EffortJointInterface</hardwareInterface>
      <mechanicalReduction>1</mechanicalReduction>
    </actuator>
  </transmission>
  <link name="r_el_link">
    <visual>
      <origin rpy="0 0 -1.5707963267948966" xyz="0 0 0"/>
      <geometry>
        <mesh filename="package://robot_description/models/robotis_op2/meshes/geo_op_right_lower-arm.stl" scale="0.001 0.001 0.001"/>
      </geometry>
      <material name="Grey">
        <color rgba="0.60 0.60 0.60 1.0"/>
      </material>
    </visual>
    <collision>
      <origin rpy="0 0 -1.5707963267948966" xyz="0 0 0"/>
      <geometry>
        <mesh filename="package://robot_description/models/robotis_op2/meshes/geo_op_right_lower-arm.stl" scale="0.001 0.001 0.001"/>
      </geometry>
      <material name="Grey">
        <color rgba="0.60 0.60 0.60 1.0"/>
      </material>
    </collision>
    <inertial>
      <origin xyz="0 0 0"/>
      <mass value="0.0592"/>
      <inertia ixx="1.0" ixy="0.0" ixz="0.0" iyy="1.0" iyz="0.0" izz="0.0"/>
    </inertial>
  </link>
  <!-- left hip yaw link -->
  <joint name="l_hip_yaw" type="revolute">
    <parent link="body_link"/>
    <child link="l_hip_yaw_link"/>
    <origin rpy="0 0 0" xyz="-0.005 0.037 -0.0907"/>
    <axis xyz="0 0 -1"/>
    <limit effort="2.8" lower="-2.6179939" upper="2.6179939" velocity="5.6548668"/>
  </joint>
  <transmission name="l_hip_yaw_tran">
    <type>transmission_interface/SimpleTransmission</type>
    <joint name="l_hip_yaw">
      <hardwareInterface>hardware_interface/EffortJointInterface</hardwareInterface>
    </joint>
    <actuator name="l_hip_yaw_motor">
      <hardwareInterface>hardware_interface/EffortJointInterface</hardwareInterface>
      <mechanicalReduction>1</mechanicalReduction>
    </actuator>
  </transmission>
  <link name="l_hip_yaw_link">
    <visual>
      <origin rpy="0 0 -1.5707963267948966" xyz="0 0 0"/>
      <geometry>
        <mesh filename="package://robot_description/models/robotis_op2/meshes/geo_op_left_hip-yaw.stl" scale="0.001 0.001 0.001"/>
      </geometry>
      <material name="Grey">
        <color rgba="0.60 0.60 0.60 1.0"/>
      </material>
    </visual>
    <collision>
      <origin rpy="0 0 -1.5707963267948966" xyz="0 0 0"/>
      <geometry>
        <mesh filename="package://robot_description/models/robotis_op2/meshes/geo_op_left_hip-yaw.stl" scale="0.001 0.001 0.001"/>
      </geometry>
      <material name="Grey">
        <color rgba="0.60 0.60 0.60 1.0"/>
      </material>
    </collision>
    <inertial>
      <origin xyz="0 0 0"/>
      <mass value="0.167"/>
      <inertia ixx="1.0" ixy="0.0" ixz="0.0" iyy="1.0" iyz="0.0" izz="0.0"/>
    </inertial>
  </link>
  <!-- left hip roll link -->
  <joint name="l_hip_roll" type="revolute">
    <parent link="l_hip_yaw_link"/>
    <child link="l_hip_roll_link"/>
    <origin rpy="0 0 0" xyz="0 0 -0.0315"/>
    <axis xyz="-1 0 0"/>
    <limit effort="2.8" lower="-2.6179939" upper="2.6179939" velocity="5.6548668"/>
  </joint>
  <transmission name="l_hip_roll_tran">
    <type>transmission_interface/SimpleTransmission</type>
    <joint name="l_hip_roll">
      <hardwareInterface>hardware_interface/EffortJointInterface</hardwareInterface>
    </joint>
    <actuator name="l_hip_roll_motor">
      <hardwareInterface>hardware_interface/EffortJointInterface</hardwareInterface>
      <mechanicalReduction>1</mechanicalReduction>
    </actuator>
  </transmission>
  <link name="l_hip_roll_link">
    <visual>
      <origin rpy="0 0 -1.5707963267948966" xyz="0 0 0"/>
      <geometry>
        <mesh filename="package://robot_description/models/robotis_op2/meshes/geo_op_left_hip-roll.stl" scale="0.001 0.001 0.001"/>
      </geometry>
      <material name="Grey">
        <color rgba="0.60 0.60 0.60 1.0"/>
      </material>
    </visual>
    <collision>
      <origin rpy="0 0 -1.5707963267948966" xyz="0 0 0"/>
      <geometry>
        <mesh filename="package://robot_description/models/robotis_op2/meshes/geo_op_left_hip-roll.stl" scale="0.001 0.001 0.001"/>
      </geometry>
      <material name="Grey">
        <color rgba="0.60 0.60 0.60 1.0"/>
      </material>
    </collision>
    <inertial>
      <origin xyz="0 0 0"/>
      <mass value="0.119"/>
      <inertia ixx="1.0" ixy="0.0" ixz="0.0" iyy="1.0" iyz="0.0" izz="0.0"/>
    </inertial>
  </link>
  <!-- left hip pitch link -->
  <joint name="l_hip_pitch" type="revolute">
    <parent link="l_hip_roll_link"/>
    <child link="l_hip_pitch_link"/>
    <origin rpy="0 0 0" xyz="0 0 0"/>
    <axis xyz="0 -1 0"/>
    <limit effort="2.8" lower="-2.6179939" upper="2.6179939" velocity="5.6548668"/>
  </joint>
  <transmission name="l_hip_pitch_tran">
    <type>transmission_interface/SimpleTransmission</type>
    <joint name="l_hip_pitch">
      <hardwareInterface>hardware_interface/EffortJointInterface</hardwareInterface>
    </joint>
    <actuator name="l_hip_pitch_motor">
      <hardwareInterface>hardware_interface/EffortJointInterface</hardwareInterface>
      <mechanicalReduction>1</mechanicalReduction>
    </actuator>
  </transmission>
  <link name="l_hip_pitch_link">
    <visual>
      <origin rpy="0 0 -1.5707963267948966" xyz="0 0 0"/>
      <geometry>
        <mesh filename="package://robot_description/models/robotis_op2/meshes/geo_op_left_thigh.stl" scale="0.001 0.001 0.001"/>
      </geometry>
      <material name="Grey">
        <color rgba="0.60 0.60 0.60 1.0"/>
      </material>
    </visual>
    <collision>
      <origin rpy="0 0 -1.5707963267948966" xyz="0 0 0"/>
      <geometry>
        <mesh filename="package://robot_description/models/robotis_op2/meshes/geo_op_left_thigh.stl" scale="0.001 0.001 0.001"/>
      </geometry>
      <material name="Grey">
        <color rgba="0.60 0.60 0.60 1.0"/>
      </material>
    </collision>
    <inertial>
      <origin xyz="0 0 0"/>
      <mass value="0.119"/>
      <inertia ixx="1.0" ixy="0.0" ixz="0.0" iyy="1.0" iyz="0.0" izz="0.0"/>
    </inertial>
  </link>
  <!-- left knee link -->
  <joint name="l_knee" type="revolute">
    <parent link="l_hip_pitch_link"/>
    <child link="l_knee_link"/>
    <origin rpy="0 0 0" xyz="0 0 -0.093"/>
    <axis xyz="0 -1 0"/>
    <limit effort="2.8" lower="-2.6179939" upper="2.6179939" velocity="5.6548668"/>
  </joint>
  <transmission name="l_knee_tran">
    <type>transmission_interface/SimpleTransmission</type>
    <joint name="l_knee">
      <hardwareInterface>hardware_interface/EffortJointInterface</hardwareInterface>
    </joint>
    <actuator name="l_knee_motor">
      <hardwareInterface>hardware_interface/EffortJointInterface</hardwareInterface>
      <mechanicalReduction>1</mechanicalReduction>
    </actuator>
  </transmission>
  <link name="l_knee_link">
    <visual>
      <origin rpy="0 0 -1.5707963267948966" xyz="0 0 0"/>
      <geometry>
        <mesh filename="package://robot_description/models/robotis_op2/meshes/geo_op_left_shin.stl" scale="0.001 0.001 0.001"/>
      </geometry>
      <material name="Grey">
        <color rgba="0.60 0.60 0.60 1.0"/>
      </material>
    </visual>
    <collision>
      <origin rpy="0 0 -1.5707963267948966" xyz="0 0 0"/>
      <geometry>
        <mesh filename="package://robot_description/models/robotis_op2/meshes/geo_op_left_shin.stl" scale="0.001 0.001 0.001"/>
      </geometry>
      <material name="Grey">
        <color rgba="0.60 0.60 0.60 1.0"/>
      </material>
    </collision>
    <inertial>
      <origin xyz="0 0 0"/>
      <mass value="0.0703"/>
      <inertia ixx="1.0" ixy="0.0" ixz="0.0" iyy="1.0" iyz="0.0" izz="0.0"/>
    </inertial>
  </link>
  <!-- left ankle pitch link -->
  <joint name="l_ank_pitch" type="revolute">
    <parent link="l_knee_link"/>
    <child link="l_ank_pitch_link"/>
    <origin rpy="0 0 0" xyz="0 0 -0.093"/>
    <axis xyz="0 1 0"/>
    <limit effort="2.8" lower="-2.6179939" upper="2.6179939" velocity="5.6548668"/>
  </joint>
  <transmission name="l_ank_pitch_tran">
    <type>transmission_interface/SimpleTransmission</type>
    <joint name="l_ank_pitch">
      <hardwareInterface>hardware_interface/EffortJointInterface</hardwareInterface>
    </joint>
    <actuator name="l_ank_pitch_motor">
      <hardwareInterface>hardware_interface/EffortJointInterface</hardwareInterface>
      <mechanicalReduction>1</mechanicalReduction>
    </actuator>
  </transmission>
  <link name="l_ank_pitch_link">
    <visual>
      <origin rpy="0 0 -1.5707963267948966" xyz="0 0 0"/>
      <geometry>
        <mesh filename="package://robot_description/models/robotis_op2/meshes/geo_op_left_ankle.stl" scale="0.001 0.001 0.001"/>
      </geometry>
      <material name="Grey">
        <color rgba="0.60 0.60 0.60 1.0"/>
      </material>
    </visual>
    <collision>
      <origin rpy="0 0 -1.5707963267948966" xyz="0 0 0"/>
      <geometry>
        <mesh filename="package://robot_description/models/robotis_op2/meshes/geo_op_left_ankle.stl" scale="0.001 0.001 0.001"/>
      </geometry>
      <material name="Grey">
        <color rgba="0.60 0.60 0.60 1.0"/>
      </material>
    </collision>
    <inertial>
      <origin xyz="0 0 0"/>
      <mass value="0.167"/>
      <inertia ixx="1.0" ixy="0.0" ixz="0.0" iyy="1.0" iyz="0.0" izz="0.0"/>
    </inertial>
  </link>
  <!-- left ankle roll link -->
  <joint name="l_ank_roll" type="revolute">
    <parent link="l_ank_pitch_link"/>
    <child link="l_ank_roll_link"/>
    <origin rpy="0 0 0" xyz="0 0 0"/>
    <axis xyz="1 0 0"/>
    <limit effort="2.8" lower="-2.6179939" upper="2.6179939" velocity="5.6548668"/>
  </joint>
  <transmission name="l_ank_roll_tran">
    <type>transmission_interface/SimpleTransmission</type>
    <joint name="l_ank_roll">
      <hardwareInterface>hardware_interface/EffortJointInterface</hardwareInterface>
    </joint>
    <actuator name="l_ank_roll_motor">
      <hardwareInterface>hardware_interface/EffortJointInterface</hardwareInterface>
      <mechanicalReduction>1</mechanicalReduction>
    </actuator>
  </transmission>
  <link name="l_ank_roll_link">
    <visual>
      <origin rpy="0 0 -1.5707963267948966" xyz="0 0 0"/>
      <geometry>
        <mesh filename="package://robot_description/models/robotis_op2/meshes/geo_op_left_foot.stl" scale="0.001 0.001 0.001"/>
      </geometry>
      <material name="Grey">
        <color rgba="0.60 0.60 0.60 1.0"/>
      </material>
    </visual>
    <collision>
      <origin rpy="0 0 -1.5707963267948966" xyz="0 0 0"/>
      <geometry>
        <mesh filename="package://robot_description/models/robotis_op2/meshes/geo_op_left_foot.stl" scale="0.001 0.001 0.001"/>
      </geometry>
      <material name="Grey">
        <color rgba="0.60 0.60 0.60 1.0"/>
      </material>
    </collision>
    <inertial>
      <origin xyz="0 0 0"/>
      <mass value="0.0794"/>
      <inertia ixx="1.0" ixy="0.0" ixz="0.0" iyy="1.0" iyz="0.0" izz="0.0"/>
    </inertial>
  </link>
  <!-- right hip yaw link -->
  <joint name="r_hip_yaw" type="revolute">
    <parent link="body_link"/>
    <child link="r_hip_yaw_link"/>
    <origin rpy="0 0 0" xyz="-0.005 -0.037 -0.0907"/>
    <axis xyz="0 0 -1"/>
    <limit effort="2.8" lower="-2.6179939" upper="2.6179939" velocity="5.6548668"/>
  </joint>
  <transmission name="r_hip_yaw_tran">
    <type>transmission_interface/SimpleTransmission</type>
    <joint name="r_hip_yaw">
      <hardwareInterface>hardware_interface/EffortJointInterface</hardwareInterface>
    </joint>
    <actuator name="r_hip_yaw_motor">
      <hardwareInterface>hardware_interface/EffortJointInterface</hardwareInterface>
      <mechanicalReduction>1</mechanicalReduction>
    </actuator>
  </transmission>
  <link name="r_hip_yaw_link">
    <visual>
      <origin rpy="0 0 -1.5707963267948966" xyz="0 0 0"/>
      <geometry>
        <mesh filename="package://robot_description/models/robotis_op2/meshes/geo_op_right_hip-yaw.stl" scale="0.001 0.001 0.001"/>
      </geometry>
      <material name="Grey">
        <color rgba="0.60 0.60 0.60 1.0"/>
      </material>
    </visual>
    <collision>
      <origin rpy="0 0 -1.5707963267948966" xyz="0 0 0"/>
      <geometry>
        <mesh filename="package://robot_description/models/robotis_op2/meshes/geo_op_right_hip-yaw.stl" scale="0.001 0.001 0.001"/>
      </geometry>
      <material name="Grey">
        <color rgba="0.60 0.60 0.60 1.0"/>
      </material>
    </collision>
    <inertial>
      <origin xyz="0 0 0"/>
      <mass value="0.167"/>
      <inertia ixx="1.0" ixy="0.0" ixz="0.0" iyy="1.0" iyz="0.0" izz="0.0"/>
    </inertial>
  </link>
  <!-- right hip roll link -->
  <joint name="r_hip_roll" type="revolute">
    <parent link="r_hip_yaw_link"/>
    <child link="r_hip_roll_link"/>
    <origin rpy="0 0 0" xyz="0 0 -0.0315"/>
    <axis xyz="-1 0 0"/>
    <limit effort="2.8" lower="-2.6179939" upper="2.6179939" velocity="5.6548668"/>
  </joint>
  <transmission name="r_hip_roll_tran">
    <type>transmission_interface/SimpleTransmission</type>
    <joint name="r_hip_roll">
      <hardwareInterface>hardware_interface/EffortJointInterface</hardwareInterface>
    </joint>
    <actuator name="r_hip_roll_motor">
      <hardwareInterface>hardware_interface/EffortJointInterface</hardwareInterface>
      <mechanicalReduction>1</mechanicalReduction>
    </actuator>
  </transmission>
  <link name="r_hip_roll_link">
    <visual>
      <origin rpy="0 0 -1.5707963267948966" xyz="0 0 0"/>
      <geometry>
        <mesh filename="package://robot_description/models/robotis_op2/meshes/geo_op_right_hip-roll.stl" scale="0.001 0.001 0.001"/>
      </geometry>
      <material name="Grey">
        <color rgba="0.60 0.60 0.60 1.0"/>
      </material>
    </visual>
    <collision>
      <origin rpy="0 0 -1.5707963267948966" xyz="0 0 0"/>
      <geometry>
        <mesh filename="package://robot_description/models/robotis_op2/meshes/geo_op_right_hip-roll.stl" scale="0.001 0.001 0.001"/>
      </geometry>
      <material name="Grey">
        <color rgba="0.60 0.60 0.60 1.0"/>
      </material>
    </collision>
    <inertial>
      <origin xyz="0 0 0"/>
      <mass value="0.119"/>
      <inertia ixx="1.0" ixy="0.0" ixz="0.0" iyy="1.0" iyz="0.0" izz="0.0"/>
    </inertial>
  </link>
  <!-- right hip pitch link -->
  <joint name="r_hip_pitch" type="revolute">
    <parent link="r_hip_roll_link"/>
    <child link="r_hip_pitch_link"/>
    <origin rpy="0 0 0" xyz="0 0 0"/>
    <axis xyz="0 1 0"/>
    <limit effort="2.8" lower="-2.6179939" upper="2.6179939" velocity="5.6548668"/>
  </joint>
  <transmission name="r_hip_pitch_tran">
    <type>transmission_interface/SimpleTransmission</type>
    <joint name="r_hip_pitch">
      <hardwareInterface>hardware_interface/EffortJointInterface</hardwareInterface>
    </joint>
    <actuator name="r_hip_pitch_motor">
      <hardwareInterface>hardware_interface/EffortJointInterface</hardwareInterface>
      <mechanicalReduction>1</mechanicalReduction>
    </actuator>
  </transmission>
  <link name="r_hip_pitch_link">
    <visual>
      <origin rpy="0 0 -1.5707963267948966" xyz="0 0 0"/>
      <geometry>
        <mesh filename="package://robot_description/models/robotis_op2/meshes/geo_op_right_thigh.stl" scale="0.001 0.001 0.001"/>
      </geometry>
      <material name="Grey">
        <color rgba="0.60 0.60 0.60 1.0"/>
      </material>
    </visual>
    <collision>
      <origin rpy="0 0 -1.5707963267948966" xyz="0 0 0"/>
      <geometry>
        <mesh filename="package://robot_description/models/robotis_op2/meshes/geo_op_right_thigh.stl" scale="0.001 0.001 0.001"/>
      </geometry>
      <material name="Grey">
        <color rgba="0.60 0.60 0.60 1.0"/>
      </material>
    </collision>
    <inertial>
      <origin xyz="0 0 0"/>
      <mass value="0.119"/>
      <inertia ixx="1.0" ixy="0.0" ixz="0.0" iyy="1.0" iyz="0.0" izz="0.0"/>
    </inertial>
  </link>
  <!-- right knee link -->
  <joint name="r_knee" type="revolute">
    <parent link="r_hip_pitch_link"/>
    <child link="r_knee_link"/>
    <origin rpy="0 0 0" xyz="0 0 -0.093"/>
    <axis xyz="0 1 0"/>
    <limit effort="2.8" lower="-2.6179939" upper="2.6179939" velocity="5.6548668"/>
  </joint>
  <transmission name="r_knee_tran">
    <type>transmission_interface/SimpleTransmission</type>
    <joint name="r_knee">
      <hardwareInterface>hardware_interface/EffortJointInterface</hardwareInterface>
    </joint>
    <actuator name="r_knee_motor">
      <hardwareInterface>hardware_interface/EffortJointInterface</hardwareInterface>
      <mechanicalReduction>1</mechanicalReduction>
    </actuator>
  </transmission>
  <link name="r_knee_link">
    <visual>
      <origin rpy="0 0 -1.5707963267948966" xyz="0 0 -0.093"/>
      <geometry>
        <mesh filename="package://robot_description/models/robotis_op2/meshes/geo_op_right_shin.stl" scale="0.001 0.001 0.001"/>
      </geometry>
      <material name="Grey">
        <color rgba="0.60 0.60 0.60 1.0"/>
      </material>
    </visual>
    <collision>
      <origin rpy="0 0 -1.5707963267948966" xyz="0 0 -0.093"/>
      <geometry>
        <mesh filename="package://robot_description/models/robotis_op2/meshes/geo_op_right_shin.stl" scale="0.001 0.001 0.001"/>
      </geometry>
      <material name="Grey">
        <color rgba="0.60 0.60 0.60 1.0"/>
      </material>
    </collision>
    <inertial>
      <origin xyz="0 0 0"/>
      <mass value="0.0703"/>
      <inertia ixx="1.0" ixy="0.0" ixz="0.0" iyy="1.0" iyz="0.0" izz="0.0"/>
    </inertial>
  </link>
  <!-- right ankle pitch link -->
  <joint name="r_ank_pitch" type="revolute">
    <parent link="r_knee_link"/>
    <child link="r_ank_pitch_link"/>
    <origin rpy="0 0 0" xyz="0 0 -0.093"/>
    <axis xyz="0 -1 0"/>
    <limit effort="2.8" lower="-2.6179939" upper="2.6179939" velocity="5.6548668"/>
  </joint>
  <transmission name="r_ank_pitch_tran">
    <type>transmission_interface/SimpleTransmission</type>
    <joint name="r_ank_pitch">
      <hardwareInterface>hardware_interface/EffortJointInterface</hardwareInterface>
    </joint>
    <actuator name="r_ank_pitch_motor">
      <hardwareInterface>hardware_interface/EffortJointInterface</hardwareInterface>
      <mechanicalReduction>1</mechanicalReduction>
    </actuator>
  </transmission>
  <link name="r_ank_pitch_link">
    <visual>
      <origin rpy="0 0 -1.5707963267948966" xyz="0 0 0"/>
      <geometry>
        <mesh filename="package://robot_description/models/robotis_op2/meshes/geo_op_right_ankle.stl" scale="0.001 0.001 0.001"/>
      </geometry>
      <material name="Grey">
        <color rgba="0.60 0.60 0.60 1.0"/>
      </material>
    </visual>
    <collision>
      <origin rpy="0 0 -1.5707963267948966" xyz="0 0 0"/>
      <geometry>
        <mesh filename="package://robot_description/models/robotis_op2/meshes/geo_op_right_ankle.stl" scale="0.001 0.001 0.001"/>
      </geometry>
      <material name="Grey">
        <color rgba="0.60 0.60 0.60 1.0"/>
      </material>
    </collision>
    <inertial>
      <origin xyz="0 0 0"/>
      <mass value="0.167"/>
      <inertia ixx="1.0" ixy="0.0" ixz="0.0" iyy="1.0" iyz="0.0" izz="0.0"/>
    </inertial>
  </link>
  <!-- right ankle roll link -->
  <joint name="r_ank_roll" type="revolute">
    <parent link="r_ank_pitch_link"/>
    <child link="r_ank_roll_link"/>
    <origin rpy="0 0 0" xyz="0 0 0"/>
    <axis xyz="1 0 0"/>
    <limit effort="2.8" lower="-2.6179939" upper="2.6179939" velocity="5.6548668"/>
  </joint>
  <transmission name="r_ank_roll_tran">
    <type>transmission_interface/SimpleTransmission</type>
    <joint name="r_ank_roll">
      <hardwareInterface>hardware_interface/EffortJointInterface</hardwareInterface>
    </joint>
    <actuator name="r_ank_roll_motor">
      <hardwareInterface>hardware_interface/EffortJointInterface</hardwareInterface>
      <mechanicalReduction>1</mechanicalReduction>
    </actuator>
  </transmission>
  <link name="r_ank_roll_link">
    <visual>
      <origin rpy="0 0 -1.5707963267948966" xyz="0 0 0"/>
      <geometry>
        <mesh filename="package://robot_description/models/robotis_op2/meshes/geo_op_right_foot.stl" scale="0.001 0.001 0.001"/>
      </geometry>
      <material name="Grey">
        <color rgba="0.60 0.60 0.60 1.0"/>
      </material>
    </visual>
    <collision>
      <origin rpy="0 0 -1.5707963267948966" xyz="0 0 0"/>
      <geometry>
        <mesh filename="package://robot_description/models/robotis_op2/meshes/geo_op_right_foot.stl" scale="0.001 0.001 0.001"/>
      </geometry>
      <material name="Grey">
        <color rgba="0.60 0.60 0.60 1.0"/>
      </material>
    </collision>
    <inertial>
      <origin xyz="0 0 0"/>
      <mass value="0.0794"/>
      <inertia ixx="1.0" ixy="0.0" ixz="0.0" iyy="1.0" iyz="0.0" izz="0.0"/>
    </inertial>
  </link>
</robot>
