<?xml version="1.0" ?>
<robot xmlns:xacro="http://ros.org/wiki/xacro">

	<!-- <xacro:property name="pi" value="3.141592654" /> -->

	<xacro:macro name="robotis_op2_larm" params="parent">

		<!-- left shoulder pitch link -->
		<joint name="l_sho_pitch" type="revolute">
			<parent link="${parent}"/>
			<child link="l_sho_pitch_link"/>
    			<origin xyz="0 0.0575 0" rpy="0 0 0" />
    			<axis xyz="0 1 0" />
   			<limit effort="2.8" velocity="5.6548668" lower="-2.6179939" upper="2.6179939" />
  		</joint>
        	<xacro:insert_transmission name="l_sho_pitch" />

		<link name="l_sho_pitch_link">
			<visual>
		        	<xacro:insert_mesh_l_sho_pitch_link />
	        	</visual>
	        	<collision>
	            		<xacro:insert_mesh_l_sho_pitch_link />
	        	</collision>
	        	<inertial>
	            		<xacro:insert_inertia_l_sho_pitch_link />
	        	</inertial>
	    	</link>

		<joint name="l_sho_roll" type="revolute">
			<parent link="l_sho_pitch_link"/>
			<child link="l_sho_roll_link"/>
    			<origin xyz="0 0.0245 -0.016" rpy="${45.0*pi/180.0} 0 0" />
    			<axis xyz="-1 0 0" />
    			<limit effort="2.8" velocity="5.648668" lower="-2.6179939" upper="2.6179939" />
  		</joint>
        	<xacro:insert_transmission name="l_sho_roll" />

		<!-- left shoulder roll link -->
		<link name="l_sho_roll_link">
			<visual>
		        	<xacro:insert_mesh_l_sho_roll_link />
	        	</visual>
	        	<collision>
	            		<xacro:insert_mesh_l_sho_roll_link />
	        	</collision>
	        	<inertial>
	            		<xacro:insert_inertia_l_sho_roll_link />
	        	</inertial>
	    	</link>

		<!-- left elbow link -->
		<joint name="l_el" type="revolute">
			<parent link="l_sho_roll_link"/>
			<child link="l_el_link"/>
    			<origin xyz="0.016 0 -0.06" rpy="0 ${-pi*0.5} 0" />
    			<axis xyz="0 1 0" />
    			<limit effort="2.8" velocity="5.6548668" lower="-2.6179939" upper="2.6179939" />
  		</joint>
        	<xacro:insert_transmission name="l_el" />

		<link name="l_el_link">
			<visual>
		        	<xacro:insert_mesh_l_el_link />
	        	</visual>
	        	<collision>
	            		<xacro:insert_mesh_l_el_link />
	        	</collision>
	        	<inertial>
	            		<xacro:insert_inertia_l_el_link />
	        	</inertial>
	    	</link>

	</xacro:macro>

	<xacro:macro name="robotis_op2_rarm" params="parent">

		<!-- right shoulder pitch link -->
		<joint name="r_sho_pitch" type="revolute">
			<parent link="${parent}"/>
			<child link="r_sho_pitch_link"/>
    			<origin xyz="0 -0.0575 0" rpy="0 0 0" />
    			<axis xyz="0 -1 0" />
    			<limit effort="2.8" velocity="5.6548668" lower="-2.6179939" upper="2.6179939" />
  		</joint>
        	<xacro:insert_transmission name="r_sho_pitch" />

		<link name="r_sho_pitch_link">
			<visual>
		        	<xacro:insert_mesh_r_sho_pitch_link />
	        	</visual>
	        	<collision>
	            		<xacro:insert_mesh_r_sho_pitch_link />
	        	</collision>
	        	<inertial>
	            		<xacro:insert_inertia_r_sho_pitch_link />
	        	</inertial>
	    	</link>

		<!-- right shoulder roll link -->
		<joint name="r_sho_roll" type="revolute">
			<parent link="r_sho_pitch_link"/>
			<child link="r_sho_roll_link"/>
    			<origin xyz="0 -0.0245 -0.016" rpy="${-45.0*pi/180.0} 0 0" />
    			<axis xyz="-1 0 0" />
    			<limit effort="2.8" velocity="5.648668" lower="-2.6179939" upper="2.6179939" />
  		</joint>
        	<xacro:insert_transmission name="r_sho_roll" />

		<link name="r_sho_roll_link">
			<visual>
		        	<xacro:insert_mesh_r_sho_roll_link />
	        	</visual>
	        	<collision>
	            		<xacro:insert_mesh_r_sho_roll_link />
	        	</collision>
	        	<inertial>
	            		<xacro:insert_inertia_r_sho_roll_link />
	        	</inertial>
	    	</link>

		<!-- right elbow link -->
		<joint name="r_el" type="revolute">
			<parent link="r_sho_roll_link"/>
			<child link="r_el_link"/>
    			<origin xyz="0.016 0 -0.06" rpy="0 ${-pi*0.5} 0" />
    			<axis xyz="0 -1 0" />
    			<limit effort="2.8" velocity="5.6548668" lower="-2.6179939" upper="2.6179939" />
  		</joint>
        	<xacro:insert_transmission name="r_el" />

		<link name="r_el_link">
			<visual>
		        	<xacro:insert_mesh_r_el_link />
	        	</visual>
	        	<collision>
	            		<xacro:insert_mesh_r_el_link />
	        	</collision>
	        	<inertial>
	            		<xacro:insert_inertia_r_el_link />
	        	</inertial>
	    	</link>

	</xacro:macro>

</robot>
